2022-05-02 01:52:56,641 INFO    MainThread:18543 [internal.py:wandb_internal():92] W&B internal server running at pid: 18543, started at: 2022-05-02 01:52:56.641539
2022-05-02 01:52:56,643 INFO    WriterThread:18543 [datastore.py:open_for_write():77] open: /home/penchekrak/SHAD/MCTS_Experiments/jax_muzero/wandb/run-20220502_015255-20st82qs/run-20st82qs.wandb
2022-05-02 01:52:56,645 DEBUG   SenderThread:18543 [sender.py:send():235] send: header
2022-05-02 01:52:56,645 DEBUG   SenderThread:18543 [sender.py:send():235] send: run
2022-05-02 01:52:56,870 ERROR   SenderThread:18543 [internal_api.py:execute():144] 404 response executing GraphQL.
2022-05-02 01:52:56,870 ERROR   SenderThread:18543 [internal_api.py:execute():145] {"errors":[{"message":"project not found","path":["upsertBucket"]}],"data":{"upsertBucket":null}}
2022-05-02 01:52:57,644 INFO    HandlerThread:18543 [handler.py:finish():790] shutting down handler
2022-05-02 01:52:57,644 INFO    WriterThread:18543 [datastore.py:close():281] close: /home/penchekrak/SHAD/MCTS_Experiments/jax_muzero/wandb/run-20220502_015255-20st82qs/run-20st82qs.wandb
2022-05-02 01:52:57,645 ERROR   MainThread:18543 [internal.py:wandb_internal():167] Thread SenderThread:
Traceback (most recent call last):
  File "/home/penchekrak/SHAD/EfficientZero/venv/lib/python3.8/site-packages/wandb/sdk/lib/retry.py", line 102, in __call__
    result = self._call_fn(*args, **kwargs)
  File "/home/penchekrak/SHAD/EfficientZero/venv/lib/python3.8/site-packages/wandb/sdk/internal/internal_api.py", line 147, in execute
    six.reraise(*sys.exc_info())
  File "/home/penchekrak/SHAD/EfficientZero/venv/lib/python3.8/site-packages/six.py", line 719, in reraise
    raise value
  File "/home/penchekrak/SHAD/EfficientZero/venv/lib/python3.8/site-packages/wandb/sdk/internal/internal_api.py", line 141, in execute
    return self.client.execute(*args, **kwargs)
  File "/home/penchekrak/SHAD/EfficientZero/venv/lib/python3.8/site-packages/wandb/vendor/gql-0.2.0/wandb_gql/client.py", line 52, in execute
    result = self._get_result(document, *args, **kwargs)
  File "/home/penchekrak/SHAD/EfficientZero/venv/lib/python3.8/site-packages/wandb/vendor/gql-0.2.0/wandb_gql/client.py", line 60, in _get_result
    return self.transport.execute(document, *args, **kwargs)
  File "/home/penchekrak/SHAD/EfficientZero/venv/lib/python3.8/site-packages/wandb/vendor/gql-0.2.0/wandb_gql/transport/requests.py", line 39, in execute
    request.raise_for_status()
  File "/home/penchekrak/SHAD/EfficientZero/venv/lib/python3.8/site-packages/requests/models.py", line 960, in raise_for_status
    raise HTTPError(http_error_msg, response=self)
requests.exceptions.HTTPError: 404 Client Error: Not Found for url: https://api.wandb.ai/graphql

During handling of the above exception, another exception occurred:

Traceback (most recent call last):
  File "/home/penchekrak/SHAD/EfficientZero/venv/lib/python3.8/site-packages/wandb/apis/normalize.py", line 24, in wrapper
    return func(*args, **kwargs)
  File "/home/penchekrak/SHAD/EfficientZero/venv/lib/python3.8/site-packages/wandb/sdk/internal/internal_api.py", line 1315, in upsert_run
    response = self.gql(mutation, variable_values=variable_values, **kwargs)
  File "/home/penchekrak/SHAD/EfficientZero/venv/lib/python3.8/site-packages/wandb/sdk/lib/retry.py", line 118, in __call__
    if not check_retry_fn(e):
  File "/home/penchekrak/SHAD/EfficientZero/venv/lib/python3.8/site-packages/wandb/util.py", line 873, in no_retry_auth
    raise CommError("Permission denied, ask the project owner to grant you access")
wandb.errors.CommError: Permission denied, ask the project owner to grant you access

During handling of the above exception, another exception occurred:

Traceback (most recent call last):
  File "/home/penchekrak/SHAD/EfficientZero/venv/lib/python3.8/site-packages/wandb/sdk/internal/internal_util.py", line 54, in run
    self._run()
  File "/home/penchekrak/SHAD/EfficientZero/venv/lib/python3.8/site-packages/wandb/sdk/internal/internal_util.py", line 105, in _run
    self._process(record)
  File "/home/penchekrak/SHAD/EfficientZero/venv/lib/python3.8/site-packages/wandb/sdk/internal/internal.py", line 312, in _process
    self._sm.send(record)
  File "/home/penchekrak/SHAD/EfficientZero/venv/lib/python3.8/site-packages/wandb/sdk/internal/sender.py", line 237, in send
    send_handler(record)
  File "/home/penchekrak/SHAD/EfficientZero/venv/lib/python3.8/site-packages/wandb/sdk/internal/sender.py", line 695, in send_run
    self._init_run(run, config_value_dict)
  File "/home/penchekrak/SHAD/EfficientZero/venv/lib/python3.8/site-packages/wandb/sdk/internal/sender.py", line 719, in _init_run
    server_run, inserted = self._api.upsert_run(
  File "/home/penchekrak/SHAD/EfficientZero/venv/lib/python3.8/site-packages/wandb/apis/normalize.py", line 62, in wrapper
    six.reraise(CommError, CommError(message, err), sys.exc_info()[2])
  File "/home/penchekrak/SHAD/EfficientZero/venv/lib/python3.8/site-packages/six.py", line 718, in reraise
    raise value.with_traceback(tb)
  File "/home/penchekrak/SHAD/EfficientZero/venv/lib/python3.8/site-packages/wandb/apis/normalize.py", line 24, in wrapper
    return func(*args, **kwargs)
  File "/home/penchekrak/SHAD/EfficientZero/venv/lib/python3.8/site-packages/wandb/sdk/internal/internal_api.py", line 1315, in upsert_run
    response = self.gql(mutation, variable_values=variable_values, **kwargs)
  File "/home/penchekrak/SHAD/EfficientZero/venv/lib/python3.8/site-packages/wandb/sdk/lib/retry.py", line 118, in __call__
    if not check_retry_fn(e):
  File "/home/penchekrak/SHAD/EfficientZero/venv/lib/python3.8/site-packages/wandb/util.py", line 873, in no_retry_auth
    raise CommError("Permission denied, ask the project owner to grant you access")
wandb.errors.CommError: Permission denied, ask the project owner to grant you access
2022-05-02 01:52:59,676 INFO    MainThread:18543 [internal.py:handle_exit():82] Internal process exited
